{
    "data_folder_path": "data/CVE-2021-28861",
    "pull_requests_urls": [
        "https://github.com/python/cpython/pull/24848"
    ],
    "cve_name": "CVE-2021-28861",
    "repo": "python/cpython",
    "warnings": {
        "cve": "CVE-2021-28861",
        "warnings": [
            {
                "type": "NOT_MODIFIED",
                "file_name": "Lib/test/test_http/test_http.py",
                "message": "not a modified file (status: FileStatus.ADDED)\n"
            },
            {
                "type": "NOT_MODIFIED",
                "file_name": "Misc/NEWS.d/next/Security/2021-03-13-21-25-29.bpo-43223.ieBVWq.rst",
                "message": "not a modified file (status: FileStatus.ADDED)\n"
            },
            {
                "type": "CANT_PATCHED",
                "file_name": "Misc/NEWS.d/next/Security/2021-03-13-21-25-29.bpo-43223.ieBVWq.rst",
                "message": "Failed to patch file."
            }
        ]
    },
    "files_extension_stats": {
        ".py": 2,
        ".rst": 1
    },
    "file_number": 3,
    "removed_files_number": 0,
    "added_files_number": 0,
    "nb_lines_affected": 20,
    "private_key_files": [],
    "languages": [
        "Python"
    ]
}